Workbook

Sheet Introduction
A1: Build a 3 Statement Financial Model from Scratch
A3: Income Statement & Cash flow=>Flow Statements (Represent Periods of Time)
A4: Balance Sheet=Represents specific period of time
A5: Income Statement=Money made and expenses
A6: Cash Flow= changes in what you own and what you owe (example off a P&L)
A9: Step 1. | B9: Build Income Statement (depreciation & bank interest blank)
A10: Step 2. | B10: Create CAPEX and depreciation schedule (assets)
A11: Step 3. | B11: Build balance sheet on historic data
A12: Step 4. | B12: Cash flow tied to balance sheet

Sheet Income Statement
A1: Mail Order Cookie Company
A2: Income Statement | B2: 1st Year | C2: 2nd Year | D2: 3rd Year | E2: 4th Year
A4: Revenue
A6: Gross Revenue | B6: =B46*B47 -> 1750000 | C6: =C46*C47 -> 2750000 | D6: =D46*D47 -> 5500000 | E6: =E46*E47 -> 11250000
A7: Refunds | B7: =B6*B48 -> 87500 | C7: =C6*C48 -> 137500 | D7: =D6*D48 -> 275000 | E7: =E6*E48 -> 562500
A8: Discounts | B8: =B6*B49 -> 140000 | C8: =C6*C49 -> 220000 | D8: =D6*D49 -> 440000 | E8: =E6*E49 -> 900000
A9: Net Revenue | B9: =B6-B7-B8 -> 1522500 | C9: =C6-C7-C8 -> 2392500 | D9: =D6-D7-D8 -> 4785000 | E9: =E6-E7-E8 -> 9787500
A11: COGS (Cost of Good Sold)
A13: Product (Material cost) | B13: =B9*B52 -> 456750 | C13: =C9*C52 -> 717750 | D13: =D9*D52 -> 1435500 | E13: =E9*E52 -> 2936250
A14: Fullfilment | B14: =B9*B53 -> 106575 | C14: =C9*C53 -> 167475 | D14: =D9*D53 -> 334950 | E14: =E9*E53 -> 685125
A15: Merchant Services | B15: =B9*B54 -> 152250 | C15: =C9*C54 -> 239250 | D15: =D9*D54 -> 478500 | E15: =E9*E54 -> 978750
A16: Total COGS | B16: =SUM(B13:B15) -> 715575 | C16: =SUM(C13:C15) -> 1124475 | D16: =SUM(D13:D15) -> 2248950 | E16: =SUM(E13:E15) -> 4600125
A18: Gross Margin | B18: =B9-B16 -> 806925 | C18: =C9-C16 -> 1268025 | D18: =D9-D16 -> 2536050 | E18: =E9-E16 -> 5187375 | G18: Net Revenue -Total COGS
A19: GM% | B19: =B18/B9 -> 0.53 | C19: =C18/C9 -> 0.53 | D19: =D18/D9 -> 0.53 | E19: =E18/E9 -> 0.53
A21: Operating Expenses
A23: Hr | B23: =B9*B57 -> 380625 | C23: =C9*C57 -> 598125 | D23: =D9*D57 -> 1196250 | E23: =E9*E57 -> 2446875
A24: Marketing | B24: =B9*B58 -> 152250 | C24: =C9*C58 -> 239250 | D24: =D9*D58 -> 478500 | E24: =E9*E58 -> 978750
A25: Misc | B25: =B9*B59 -> 76125 | C25: =C9*C59 -> 119625 | D25: =D9*D59 -> 239250 | E25: =E9*E59 -> 489375
A26: Depreciation (other model) | B26: ='Capex and Depreciation Schedule'!C13 -> 26666.667 | C26: ='Capex and Depreciation Schedule'!D13 -> 60000 | D26: ='Capex and Depreciation Schedule'!E13 -> 99333.333 | E26: ='Capex and Depreciation Schedule'!F13 -> 82666.667
A27: Total OPEX (Operating Expenses) | B27: =SUM(B23:B26) -> 635666.67 | C27: =SUM(C23:C26) -> 1017000 | D27: =SUM(D23:D26) -> 2013333.3 | E27: =SUM(E23:E26) -> 3997666.7
A29: Operating Income | B29: =B18-B27 -> 171258.33 | C29: =C18-C27 -> 251025 | D29: =D18-D27 -> 522716.67 | E29: =E18-E27 -> 1189708.3 | G29: Gross Margin - Total OPEX
A31: Interest (other model) | B31: ='Balance Sheet'!C44 -> 175000 | C31: ='Balance Sheet'!D44 -> 196000 | D31: ='Balance Sheet'!E44 -> 147000 | E31: ='Balance Sheet'!F44 -> 98000
A33: NI (Net Income) Before Taxes | B33: =B29-B31 -> -3741.6667 | C33: =C29-C31 -> 55025 | D33: =D29-D31 -> 375716.67 | E33: =E29-E31 -> 1091708.3 | G33: Operating income - NI before Taxes
A35: Taxes | B35: =B33*B64 -> -823.16667 | C35: =C33*C64 -> 12105.5 | D35: =D33*D64 -> 82657.667 | E35: =E33*E64 -> 240175.83
A37: Net Income | B37: =B33-B35 -> -2918.5 | C37: =C33-C35 -> 42919.5 | D37: =D33-D35 -> 293059 | E37: =E33-E35 -> 851532.5 | G37: NI - Taxes
A38: NI% | B38: =B37/B9 -> -0.001916913 | C38: =C37/C9 -> 0.017939185 | D38: =D37/D9 -> 0.06124535 | E38: =E37/E9 -> 0.087002043
A40: EBITDA | B40: =B29+B26 -> 197925 | C40: =C29+C26 -> 311025 | D40: =D29+D26 -> 622050 | E40: =E29+E26 -> 1272375 | G40: Earning Before Interest Tax Depreciation Amortization | H40: Operating income + Depreciation
A43: MY ASSUMPTIONS
A45: Revenue
A46: New Customers | B46: 70000 | C46: 110000 | D46: 220000 | E46: 450000
A47: AOV (Average Order Value) | B47: 25 | C47: 25 | D47: 25 | E47: 25
A48: Refunds (as % rev) | B48: 0.05 | C48: 0.05 | D48: 0.05 | E48: 0.05
A49: Discounts | B49: 0.08 | C49: 0.08 | D49: 0.08 | E49: 0.08
A51: COGS (Cost of Goods Sold)
A52: Product (Materials cost) | B52: 0.3 | C52: 0.3 | D52: 0.3 | E52: 0.3
A53: Fullfillment | B53: 0.07 | C53: 0.07 | D53: 0.07 | E53: 0.07
A54: Merchant Services | B54: 0.1 | C54: 0.1 | D54: 0.1 | E54: 0.1
A56: Operating Expenses
A57: HR | B57: 0.25 | C57: 0.25 | D57: 0.25 | E57: 0.25
A58: Marketing | B58: 0.1 | C58: 0.1 | D58: 0.1 | E58: 0.1
...

Sheet Capex and Depreciation Schedule
A1: CAPEX & Depreciation | B1: Useful Life (Years) | C1: Year 1 | D1: Year 2 | E1: Year 3 | F1: Year4
A3: CAPEX
A4: Laptops | B4: 5 | C4: 50000
A5: Custom Software Apps | B5: 3 | C5: 50000 | D5: 100000 | E5: 100000
A6: New Ovens | B6: 5 | E6: 30000
A7: Total CAPEX | C7: =SUM(C4:C6) -> 100000 | D7: =SUM(D4:D6) -> 100000 | E7: =SUM(E4:E6) -> 130000 | F7: =SUM(F4:F6) -> 0
A9: Depreciaiton
A10: Laptops | C10: =$C$4/$B$4 -> 10000 | D10: =$C$4/$B$4 -> 10000 | E10: =$C$4/$B$4 -> 10000 | F10: =$C$4/$B$4 -> 10000
A11: Custom Software Apps | C11: =$C$5/$B$5 -> 16666.667 | D11: =$C$5/$B$5 + $D$5/$B$5 -> 50000 | E11: =$C$5/$B$5 + $D$5/$B$5 + $E$5/$B$5 -> 83333.333 | F11: =$D$5/$B$5 + $E$5/$B$5 + $F$5/$B$5 -> 66666.667
A12: New Ovens | E12: =$E$6/$B$6 -> 6000 | F12: =$E$6/$B$6 -> 6000
A13: Total D&A (Depreciation & Amortization | C13: =SUM(C10:C12) -> 26666.667 | D13: =SUM(D10:D12) -> 60000 | E13: =SUM(E10:E12) -> 99333.333 | F13: =SUM(F10:F12) -> 82666.667

Sheet Balance Sheet
A1: Balance Sheet | B1: Dec 31-Year 0 | C1: Year 1 | D1: Year 2 | E1: Year 3 | F1: Year 4
B2: Historicals
A3: ASSETS
A5: Cash | B5: 4250000 | C5: ='Cash Flow Statement'!B23 -> 504648.17 | D5: ='Cash Flow Statement'!C23 -> 1761644.5 | E5: ='Cash Flow Statement'!D23 -> 1129867.3 | F5: ='Cash Flow Statement'!E23 -> 2227974.2
A6: Account Receivable (AR) | B6: 120000 | C6: ='Income Statement'!B9*'Balance Sheet'!C37 -> 76125 | D6: ='Income Statement'!C9*D37 -> 119625 | E6: ='Income Statement'!D9*E37 -> 239250 | F6: ='Income Statement'!E9*F37 -> 489375 | H6: Net Revenue x AR%
A7: Total Current Assets | B7: =SUM(B5:B6) -> 4370000 | C7: =SUM(C5:C6) -> 580773.17 | D7: =SUM(D5:D6) -> 1881269.5 | E7: =SUM(E5:E6) -> 1369117.3 | F7: =SUM(F5:F6) -> 2717349.2
A9: Fixed Assets | B9: 40000 | C9: =B9+'Capex and Depreciation Schedule'!C7 -> 140000 | D9: =C9+'Capex and Depreciation Schedule'!D7 -> 240000 | E9: =D9+'Capex and Depreciation Schedule'!E7 -> 370000 | F9: =E9+'Capex and Depreciation Schedule'!F7 -> 370000 | H9: Accumulated of CAPEX
A10: Accumulated Depreciation | B10: -10000 | C10: =B10-'Capex and Depreciation Schedule'!C13 -> -36666.667 | D10: =C10-'Capex and Depreciation Schedule'!D13 -> -96666.667 | E10: =D10-'Capex and Depreciation Schedule'!E13 -> -196000 | F10: =E10-'Capex and Depreciation Schedule'!F13 -> -278666.67
A11: Net Fixed Assets | B11: =SUM(B9:B10) -> 30000 | C11: =SUM(C9:C10) -> 103333.33 | D11: =SUM(D9:D10) -> 143333.33 | E11: =SUM(E9:E10) -> 174000 | F11: =SUM(F9:F10) -> 91333.333
A13: Total Assets | B13: =SUM(B7,B11) -> 4400000 | C13: =SUM(C7,C11) -> 684106.5 | D13: =SUM(D7,D11) -> 2024602.8 | E13: =SUM(E7,E11) -> 1543117.3 | F13: =SUM(F7,F11) -> 2808682.5
A15: LIABILITIES
A17: Accounts Payable (AP) | B17: 75000 | C17: ='Income Statement'!B9*'Balance Sheet'!C38 -> 91350 | D17: ='Income Statement'!C9*'Balance Sheet'!D38 -> 143550 | E17: ='Income Statement'!D9*'Balance Sheet'!E38 -> 287100 | F17: ='Income Statement'!E9*'Balance Sheet'!F38 -> 587250 | H17: Net Revenue x AP%
A18: Deferred Revenue | B18: 25000 | C18: ='Income Statement'!B9*'Balance Sheet'!C39 -> 45675 | D18: ='Income Statement'!C9*'Balance Sheet'!D39 -> 95700 | E18: ='Income Statement'!D9*'Balance Sheet'!E39 -> 239250 | F18: ='Income Statement'!E9*'Balance Sheet'!F39 -> 783000 | H18: Net Revenue x Deferred Revenue%
A19: Total Current Assets | B19: =SUM(B17:B18) -> 100000 | C19: =SUM(C17:C18) -> 137025 | D19: =SUM(D17:D18) -> 239250 | E19: =SUM(E17:E18) -> 526350 | F19: =SUM(F17:F18) -> 1370250
A21: Long Term Debt | B21: 3000000 | C21: =B21-C42 -> 2500000 | D21: =C21+D41-D42 -> 2800000 | E21: =D21-E42 -> 2100000 | F21: =E21-F42 -> 1400000 | H21: Balance of Debt
A23: Total Liabilities | B23: =SUM(B19,B21) -> 3100000 | C23: =SUM(C19,C21) -> 2637025 | D23: =SUM(D19,D21) -> 3039250 | E23: =SUM(E19,E21) -> 2626350 | F23: =SUM(F19,F21) -> 2770250
A25: EQUITY
A27: Common Stock | B27: 50000 | C27: 50000 | D27: 50000 | E27: 50000 | F27: 50000
A28: Retained Earnings | B28: 1250000 | C28: =B28+'Income Statement'!B37 -> 1247081.5 | D28: =C28+'Income Statement'!C37 -> 1290001 | E28: =D28+'Income Statement'!D37 -> 1583060 | F28: =E28+'Income Statement'!E37 -> 2434592.5
A29: Total Shareholders Equity | B29: =SUM(B27:B28) -> 1300000 | C29: =SUM(C27:C28) -> 1297081.5 | D29: =SUM(D27:D28) -> 1340001 | E29: =SUM(E27:E28) -> 1633060 | F29: =SUM(F27:F28) -> 2484592.5
A31: Liabilities & Shareholders Equity | B31: =B23+B29 -> 4400000 | C31: =C23+C29 -> 3934106.5 | D31: =D23+D29 -> 4379251 | E31: =E23+E29 -> 4259410 | F31: =F23+F29 -> 5254842.5
A33: Balance Check | B33: =B13-B31 -> 0 | C33: =C13-C31 -> -3250000 | D33: =D13-D31 -> -2354648.2 | E33: =E13-E31 -> -2716292.7 | F33: =F13-F31 -> -2446160
A35: ASSUMPTIONS
A37: AR (% of revenue) | C37: 0.05 | D37: 0.05 | E37: 0.05 | F37: 0.05
A38: AP (% of revenue) | C38: 0.06 | D38: 0.06 | E38: 0.06 | F38: 0.06
A39: Deferred Revenue | C39: 0.03 | D39: 0.04 | E39: 0.05 | F39: 0.08
A41: Net Borrowing (New Debt Taken On) | D41: 1000000
A42: Debt Payments | C42: 500000 | D42: 700000 | E42: 700000 | F42: 700000
A43: Interest Rate | C43: 0.07 | D43: 0.07 | E43: 0.07 | F43: 0.07
A44: Interest Payments | C44: =C21*C43 -> 175000 | D44: =D21*D43 -> 196000 | E44: =E21*E43 -> 147000 | F44: =F21*F43 -> 98000 | H44: Long Term Debt x Interest Rate

Sheet Cash Flow Statement
A1: Cash Flow Statement | B1: 1st Year | C1: 2nd Year | D1: 3rd Year | E1: 4th Year
A3: Net Income | B3: ='Income Statement'!B37 -> -2918.5 | C3: ='Income Statement'!C37 -> 42919.5 | D3: ='Income Statement'!D37 -> 293059 | E3: ='Income Statement'!E37 -> 851532.5
A5: Operating Activities
A6: Depreciations | B6: ='Income Statement'!B26 -> 26666.667 | C6: ='Income Statement'!C26 -> 60000 | D6: ='Income Statement'!D26 -> 99333.333 | E6: ='Income Statement'!E26 -> 82666.667
A7: Change in AR | B7: ='Balance Sheet'!B6-'Balance Sheet'!C6 -> 43875 | C7: ='Balance Sheet'!C6-'Balance Sheet'!D6 -> -43500 | D7: ='Balance Sheet'!D6-'Balance Sheet'!E6 -> -119625 | E7: ='Balance Sheet'!E6-'Balance Sheet'!F6 -> -250125 | G7: previous year - this year
A8: Change in AP | B8: ='Balance Sheet'!C17-'Balance Sheet'!B17 -> 16350 | C8: ='Balance Sheet'!D17-'Balance Sheet'!C17 -> 52200 | D8: ='Balance Sheet'!E17-'Balance Sheet'!D17 -> 143550 | E8: ='Balance Sheet'!F17-'Balance Sheet'!E17 -> 300150 | G8: this year - previous year
A9: Change in Def Rev | B9: ='Balance Sheet'!C18-'Balance Sheet'!B18 -> 20675 | C9: ='Balance Sheet'!D18-'Balance Sheet'!C18 -> 50025 | D9: ='Balance Sheet'!E18-'Balance Sheet'!D18 -> 143550 | E9: ='Balance Sheet'!F18-'Balance Sheet'!E18 -> 543750
A10: Operating Cash Flow | B10: =B3+SUM(B6:B9) -> 104648.17 | C10: =C3+SUM(C6:C9) -> 161644.5 | D10: =D3+SUM(D6:D9) -> 559867.33 | E10: =E3+SUM(E6:E9) -> 1527974.2 | G10: Net Income + Operating Activities
A12: Investing Activities
A14: CAPEX | B14: ='Capex and Depreciation Schedule'!C7 -> 100000 | C14: ='Capex and Depreciation Schedule'!D7 -> 100000 | D14: ='Capex and Depreciation Schedule'!E7 -> 130000 | E14: ='Capex and Depreciation Schedule'!F7 -> 0
A16: Free Cash Flow | B16: =B10-B14 -> 4648.1667 | C16: =C10-C14 -> 61644.5 | D16: =D10-D14 -> 429867.33 | E16: =E10-E14 -> 1527974.2 | G16: Operating Cash Flow - CAPEX
A18: Financing Activities
A19: Debt Repayment | B19: ='Balance Sheet'!C42 -> 500000 | C19: ='Balance Sheet'!D42 -> 700000 | D19: ='Balance Sheet'!E42 -> 700000 | E19: ='Balance Sheet'!F42 -> 700000
A20: Net Borrowing | B20: ='Balance Sheet'!C41 -> 0 | C20: ='Balance Sheet'!D41 -> 1000000 | D20: ='Balance Sheet'!E41 -> 0 | E20: ='Balance Sheet'!F41 -> 0
A21: NFC From Financing | B21: =SUM(B19:B20) -> 500000 | C21: =SUM(C19:C20) -> 1700000 | D21: =SUM(D19:D20) -> 700000 | E21: =SUM(E19:E20) -> 700000
A23: Net Cash Flow | B23: =B16+B21 -> 504648.17 | C23: =C16+C21 -> 1761644.5 | D23: =D16+D21 -> 1129867.3 | E23: =E16+E21 -> 2227974.2
